Internal Server Error: /ais/api/v1/process
Traceback (most recent call last):
  File "/usr/local/lib/python3.12/site-packages/redis/connection.py", line 276, in connect
    sock = self.retry.call_with_retry(
           ^^^^^^^^^^^^^^^^^^^^^^^^^^^
  File "/usr/local/lib/python3.12/site-packages/redis/retry.py", line 46, in call_with_retry
    return do()
           ^^^^
  File "/usr/local/lib/python3.12/site-packages/redis/connection.py", line 277, in <lambda>
    lambda: self._connect(), lambda error: self.disconnect(error)
            ^^^^^^^^^^^^^^^
  File "/usr/local/lib/python3.12/site-packages/redis/connection.py", line 639, in _connect
    raise err
  File "/usr/local/lib/python3.12/site-packages/redis/connection.py", line 627, in _connect
    sock.connect(socket_address)
ConnectionRefusedError: [Errno 111] Connection refused

During handling of the above exception, another exception occurred:

Traceback (most recent call last):
  File "/usr/local/lib/python3.12/site-packages/django/core/handlers/exception.py", line 55, in inner
    response = get_response(request)
               ^^^^^^^^^^^^^^^^^^^^^
  File "/usr/local/lib/python3.12/site-packages/django/core/handlers/base.py", line 197, in _get_response
    response = wrapped_callback(request, *callback_args, **callback_kwargs)
               ^^^^^^^^^^^^^^^^^^^^^^^^^^^^^^^^^^^^^^^^^^^^^^^^^^^^^^^^^^^^
  File "/app/ais/views.py", line 42, in process
    resData = hongkong_land_features_start_process(input_params)
              ^^^^^^^^^^^^^^^^^^^^^^^^^^^^^^^^^^^^^^^^^^^^^^^^^^
  File "/app/ais/aimodels/hkLandFeatures/enter.py", line 237, in StartProcess
    async_task(task_start, input_params, q_options={"task_name": input_params.get("uuid"), "hook": task_finish})
  File "/usr/local/lib/python3.12/site-packages/django_q/tasks.py", line 74, in async_task
    enqueue_id = broker.enqueue(pack)
                 ^^^^^^^^^^^^^^^^^^^^
  File "/usr/local/lib/python3.12/site-packages/django_q/brokers/redis_broker.py", line 19, in enqueue
    return self.connection.rpush(self.list_key, task)
           ^^^^^^^^^^^^^^^^^^^^^^^^^^^^^^^^^^^^^^^^^^
  File "/usr/local/lib/python3.12/site-packages/redis/commands/core.py", line 2825, in rpush
    return self.execute_command("RPUSH", name, *values)
           ^^^^^^^^^^^^^^^^^^^^^^^^^^^^^^^^^^^^^^^^^^^^
  File "/usr/local/lib/python3.12/site-packages/redis/client.py", line 542, in execute_command
    conn = self.connection or pool.get_connection(command_name, **options)
                              ^^^^^^^^^^^^^^^^^^^^^^^^^^^^^^^^^^^^^^^^^^^^
  File "/usr/local/lib/python3.12/site-packages/redis/connection.py", line 1109, in get_connection
    connection.connect()
  File "/usr/local/lib/python3.12/site-packages/redis/connection.py", line 282, in connect
    raise ConnectionError(self._error_message(e))
redis.exceptions.ConnectionError: Error 111 connecting to 192.168.3.247:6379. Connection refused.
