06:17:10 [Q] INFO Q Cluster india-enemy-single-fourteen starting.
06:17:10 [Q] ERROR Can not connect to Redis server.
Process Process-3d62de73004d4c2184cd107e10a9e54e:
Traceback (most recent call last):
  File "/usr/local/lib/python3.12/site-packages/redis/connection.py", line 276, in connect
    sock = self.retry.call_with_retry(
           ^^^^^^^^^^^^^^^^^^^^^^^^^^^
  File "/usr/local/lib/python3.12/site-packages/redis/retry.py", line 46, in call_with_retry
    return do()
           ^^^^
  File "/usr/local/lib/python3.12/site-packages/redis/connection.py", line 277, in <lambda>
    lambda: self._connect(), lambda error: self.disconnect(error)
            ^^^^^^^^^^^^^^^
  File "/usr/local/lib/python3.12/site-packages/redis/connection.py", line 639, in _connect
    raise err
  File "/usr/local/lib/python3.12/site-packages/redis/connection.py", line 627, in _connect
    sock.connect(socket_address)
ConnectionRefusedError: [Errno 111] Connection refused

During handling of the above exception, another exception occurred:

Traceback (most recent call last):
  File "/usr/local/lib/python3.12/multiprocessing/process.py", line 314, in _bootstrap
    self.run()
  File "/usr/local/lib/python3.12/multiprocessing/process.py", line 108, in run
    self._target(*self._args, **self._kwargs)
  File "/usr/local/lib/python3.12/site-packages/django_q/cluster.py", line 158, in __init__
    self.start()
  File "/usr/local/lib/python3.12/site-packages/django_q/cluster.py", line 165, in start
    self.broker.ping()
  File "/usr/local/lib/python3.12/site-packages/django_q/brokers/redis_broker.py", line 40, in ping
    raise e
  File "/usr/local/lib/python3.12/site-packages/django_q/brokers/redis_broker.py", line 37, in ping
    return self.connection.ping()
           ^^^^^^^^^^^^^^^^^^^^^^
  File "/usr/local/lib/python3.12/site-packages/redis/commands/core.py", line 1217, in ping
    return self.execute_command("PING", **kwargs)
           ^^^^^^^^^^^^^^^^^^^^^^^^^^^^^^^^^^^^^^
  File "/usr/local/lib/python3.12/site-packages/redis/client.py", line 542, in execute_command
    conn = self.connection or pool.get_connection(command_name, **options)
                              ^^^^^^^^^^^^^^^^^^^^^^^^^^^^^^^^^^^^^^^^^^^^
  File "/usr/local/lib/python3.12/site-packages/redis/connection.py", line 1109, in get_connection
    connection.connect()
  File "/usr/local/lib/python3.12/site-packages/redis/connection.py", line 282, in connect
    raise ConnectionError(self._error_message(e))
redis.exceptions.ConnectionError: Error 111 connecting to 192.168.3.247:6379. Connection refused.
